Traceback (most recent call last):
  File "/opt/anaconda3/lib/python3.8/site-packages/jupyter_cache/executors/utils.py", line 51, in single_nb_execution
    executenb(
  File "/opt/anaconda3/lib/python3.8/site-packages/nbclient/client.py", line 1087, in execute
    return NotebookClient(nb=nb, resources=resources, km=km, **kwargs).execute()
  File "/opt/anaconda3/lib/python3.8/site-packages/nbclient/util.py", line 74, in wrapped
    return just_run(coro(*args, **kwargs))
  File "/opt/anaconda3/lib/python3.8/site-packages/nbclient/util.py", line 53, in just_run
    return loop.run_until_complete(coro)
  File "/opt/anaconda3/lib/python3.8/asyncio/base_events.py", line 616, in run_until_complete
    return future.result()
  File "/opt/anaconda3/lib/python3.8/site-packages/nbclient/client.py", line 540, in async_execute
    await self.async_execute_cell(
  File "/opt/anaconda3/lib/python3.8/site-packages/nbclient/client.py", line 832, in async_execute_cell
    self._check_raise_for_error(cell, exec_reply)
  File "/opt/anaconda3/lib/python3.8/site-packages/nbclient/client.py", line 740, in _check_raise_for_error
    raise CellExecutionError.from_cell_and_msg(cell, exec_reply['content'])
nbclient.exceptions.CellExecutionError: An error occurred while executing the following cell:
------------------
from sqlite3 import connect
conn = connect(':memory:')
df = pd.DataFrame(data=[[0, '10/11/12'], [1, '12/11/10']],
                  columns=['int_column', 'date_column'])
df.to_sql('test_data', conn)
------------------

[0;31m---------------------------------------------------------------------------[0m
[0;31mNameError[0m                                 Traceback (most recent call last)
[0;32m<ipython-input-1-83368f4cc143>[0m in [0;36m<module>[0;34m[0m
[1;32m      1[0m [0;32mfrom[0m [0msqlite3[0m [0;32mimport[0m [0mconnect[0m[0;34m[0m[0;34m[0m[0m
[1;32m      2[0m [0mconn[0m [0;34m=[0m [0mconnect[0m[0;34m([0m[0;34m':memory:'[0m[0;34m)[0m[0;34m[0m[0;34m[0m[0m
[0;32m----> 3[0;31m df = pd.DataFrame(data=[[0, '10/11/12'], [1, '12/11/10']],
[0m[1;32m      4[0m                   columns=['int_column', 'date_column'])
[1;32m      5[0m [0mdf[0m[0;34m.[0m[0mto_sql[0m[0;34m([0m[0;34m'test_data'[0m[0;34m,[0m [0mconn[0m[0;34m)[0m[0;34m[0m[0;34m[0m[0m

[0;31mNameError[0m: name 'pd' is not defined
NameError: name 'pd' is not defined

